<?xml version="1.0" ?>
<!-- =================================================================================== -->
<!-- |    This document was autogenerated by xacro from /home/neofelis/vrx_ws/my_wamv/revised_urdf.urdf | -->
<!-- |    EDITING THIS FILE BY HAND IS NOT RECOMMENDED                                 | -->
<!-- =================================================================================== -->
<!-- This URDF was automatically created by SolidWorks to URDF Exporter! Originally created by Stephen Brawner (brawner@gmail.com) 
     Commit Version: 1.6.0-4-g7f85cfe  Build Version: 1.6.7995.38578
     For more information, please see http://wiki.ros.org/sw_urdf_exporter -->
<robot name="blueboat_urdf">
  <link name="base_link">
    <inertial>
      <origin rpy="0 0 0" xyz="0.385513736392934 0.0490743542863906 -0.613621250724049"/>
      <mass value="28.784"/>
      <inertia ixx="3.34" ixy="0.09" ixz="-0.25" iyy="3.42" iyz="0.05" izz="3.68"/>
    </inertial>
    <visual>
      <origin rpy="0 0 0" xyz="0 0 0"/>
      <geometry>
        <mesh filename="package://my_wamv/meshes/base_link.stl"/>
      </geometry>
      <material name="red">
        <color rgba="0.8 0.1 0.1 1"/>
      </material>
    </visual>
    <collision>
      <origin rpy="0 0 0" xyz="0 0 0"/>
      <geometry>
        <mesh filename="package://my_wamv/meshes/base_link.stl"/>
      </geometry>
    </collision>
  </link>
  <link name="left_link">
    <inertial>
      <origin rpy="0 0 0" xyz="0.0310805605236868 -0.00261283718392713 -1.96268754248941E-07"/>
      <mass value="0.0185850494502652"/>
      <inertia ixx="0.00000720" ixy="-0.00000013" ixz="0.00000003" iyy="0.00000566" iyz="0" izz="0.00000816"/>
    </inertial>
    <visual>
      <origin rpy="0 0 0" xyz="0 0 0"/>
      <geometry>
        <mesh filename="package://my_wamv/meshes/left_link.stl"/>
      </geometry>
      <material name="grey">
        <color rgba="0.250980392156863 0.250980392156863 0.250980392156863 1"/>
      </material>
    </visual>
    <collision>
      <origin rpy="0 0 0" xyz="0 0 0"/>
      <geometry>
        <mesh filename="package://my_wamv/meshes/left_link.stl"/>
      </geometry>
    </collision>
  </link>
  <joint name="left_joint" type="continuous">
    <origin rpy="0 0 -1.5708" xyz="0.75097 1.1523 -0.272"/>
    <parent link="base_link"/>
    <child link="left_link"/>
    <axis xyz="-0.99648 0.083772 0"/>
    <limit effort="43.18" velocity="100"/>
    <dynamics damping="0.1"/>
  </joint>
  <link name="right_link">
    <inertial>
      <origin rpy="0 0 0" xyz="0.031080555088574 -0.00261291005419406 1.85383385586935E-07"/>
      <mass value="0.0185850515024319"/>
      <inertia ixx="0.00000720" ixy="-0.00000013" ixz="0.00000003" iyy="0.00000566" iyz="0" izz="0.00000816"/>
    </inertial>
    <visual>
      <origin rpy="0 0 0" xyz="0 0 0"/>
      <geometry>
        <mesh filename="package://my_wamv/meshes/right_link.stl"/>
      </geometry>
      <material name="grey">
        <color rgba="0.250980392156863 0.250980392156863 0.250980392156863 1"/>
      </material>
    </visual>
    <collision>
      <origin rpy="0 0 0" xyz="0 0 0"/>
      <geometry>
        <mesh filename="package://my_wamv/meshes/right_link.stl"/>
      </geometry>
    </collision>
  </link>
  <joint name="right_joint" type="continuous">
    <origin rpy="0 0 -1.5708" xyz="0.15705 1.2022 -0.272"/>
    <parent link="base_link"/>
    <child link="right_link"/>
    <axis xyz="-0.99648 0.083772 0"/>
    <limit effort="43.18" velocity="100"/>
    <dynamics damping="0.1"/>
  </joint>
  <gazebo>
    <plugin filename="gz-sim-thruster-system" name="gz::sim::systems::Thruster">
      <joint_name>left_joint</joint_name>
      <thrust_coefficient>0.004422</thrust_coefficient>
      <fluid_density>1000</fluid_density>
      <propeller_diameter>0.2</propeller_diameter>
      <velocity_control>true</velocity_control>
      <!-- max total thrust / 2 -->
      <max_thrust_cmd>2353.53383667818</max_thrust_cmd>
      <namespace>wamv</namespace>
      <topic>thrusters/left/thrust</topic>
      <!-- Not used by Gazebo but used to run the bridge easily -->
      <name>left</name>
    </plugin>
    <!-- Right Thruster -->
    <plugin filename="gz-sim-thruster-system" name="gz::sim::systems::Thruster">
      <joint_name>wamv/right_joint</joint_name>
      <thrust_coefficient>0.004422</thrust_coefficient>
      <fluid_density>1000</fluid_density>
      <propeller_diameter>0.2</propeller_diameter>
      <velocity_control>true</velocity_control>
      <!-- max total thrust / 2 -->
      <max_thrust_cmd>2353.53383667818</max_thrust_cmd>
      <namespace>wamv</namespace>
      <topic>thrusters/right/thrust</topic>
      <!-- Not used by Gazebo but used to run the bridge easily -->
      <name>right</name>
    </plugin>
  </gazebo>
  <gazebo>
    <!-- Left hull -->
    <plugin filename="libSurface.so" name="vrx::Surface">
      <link_name>base_link</link_name>
      <hull_length>1.04</hull_length>
      <hull_radius>0.264</hull_radius>
      <fluid_level>0.1</fluid_level>
      <points>
        <point>0.6 1.03 0</point>
        <point>-1.4 1.03 0</point>
      </points>
      <wavefield>
        <topic>/vrx/wavefield/parameters</topic>
      </wavefield>
    </plugin>
    <!-- Right hull -->
    <plugin filename="libSurface.so" name="vrx::Surface">
      <link_name>base_link</link_name>
      <hull_length>1.04</hull_length>
      <hull_radius>0.264</hull_radius>
      <fluid_level>0.1</fluid_level>
      <points>
        <point>0.6 -1.03 0</point>
        <point>-1.4 -1.03 0</point>
      </points>
      <wavefield>
        <topic>/vrx/wavefield/parameters</topic>
      </wavefield>
    </plugin>
    <!-- Hydrodynamics -->
    <plugin filename="gz-sim-hydrodynamics-system" name="gz::sim::systems::Hydrodynamics">
      <link_name>base_link</link_name>
      <xDotU>0.0</xDotU>
      <yDotV>0.0</yDotV>
      <nDotR>0.0</nDotR>
      <xU>-51.3</xU>
      <xAbsU>-72.4</xAbsU>
      <yV>-40.0</yV>
      <yAbsV>0.0</yAbsV>
      <zW>-500.0</zW>
      <kP>-50.0</kP>
      <mQ>-50.0</mQ>
      <nR>-400.0</nR>
      <nAbsR>0.0</nAbsR>
    </plugin>
  </gazebo>
</robot>
